Traceback (most recent call last):
  File "/content/drive/Othercomputers/My Laptop/source/intern_yolov5/yolov7-main/utils/google_utils.py", line 26, in attempt_download
    assets = [x['name'] for x in response['assets']]  # release assets
KeyError: 'assets'
During handling of the above exception, another exception occurred:
Traceback (most recent call last):
  File "train.py", line 615, in <module>
    train(hyp, opt, device, tb_writer)
  File "train.py", line 86, in train
    attempt_download(weights)  # download if not found locally
  File "/content/drive/Othercomputers/My Laptop/source/intern_yolov5/yolov7-main/utils/google_utils.py", line 30, in attempt_download
    tag = subprocess.check_output('git tag', shell=True).decode().split()[-1]
IndexError: list index out of range